[31m[1mERROR   [0m asyncio:base_events.py:1826 Task exception was never retrieved
future: <Task finished name='Task-31' coro=<AsyncClient.aclose() done, defined at C:\Users\aramani\PycharmProjects\PyRITxAllurexApplause\.venv\Lib\site-packages\httpx\_client.py:2024> exception=RuntimeError('Event loop is closed')>
Traceback (most recent call last):
  File "C:\Users\aramani\PycharmProjects\PyRITxAllurexApplause\.venv\Lib\site-packages\httpx\_client.py", line 2031, in aclose
    await self._transport.aclose()
  File "C:\Users\aramani\PycharmProjects\PyRITxAllurexApplause\.venv\Lib\site-packages\httpx\_transports\default.py", line 389, in aclose
    await self._pool.aclose()
  File "C:\Users\aramani\PycharmProjects\PyRITxAllurexApplause\.venv\Lib\site-packages\httpcore\_async\connection_pool.py", line 353, in aclose
    await self._close_connections(closing_connections)
  File "C:\Users\aramani\PycharmProjects\PyRITxAllurexApplause\.venv\Lib\site-packages\httpcore\_async\connection_pool.py", line 345, in _close_connections
    await connection.aclose()
  File "C:\Users\aramani\PycharmProjects\PyRITxAllurexApplause\.venv\Lib\site-packages\httpcore\_async\connection.py", line 173, in aclose
    await self._connection.aclose()
  File "C:\Users\aramani\PycharmProjects\PyRITxAllurexApplause\.venv\Lib\site-packages\httpcore\_async\http11.py", line 258, in aclose
    await self._network_stream.aclose()
  File "C:\Users\aramani\PycharmProjects\PyRITxAllurexApplause\.venv\Lib\site-packages\httpcore\_backends\anyio.py", line 53, in aclose
    await self._stream.aclose()
  File "C:\Users\aramani\PycharmProjects\PyRITxAllurexApplause\.venv\Lib\site-packages\anyio\streams\tls.py", line 201, in aclose
    await self.transport_stream.aclose()
  File "C:\Users\aramani\PycharmProjects\PyRITxAllurexApplause\.venv\Lib\site-packages\anyio\_backends\_asyncio.py", line 1306, in aclose
    self._transport.close()
  File "C:\Users\aramani\AppData\Local\Programs\Python\Python312\Lib\asyncio\proactor_events.py", line 109, in close
    self._loop.call_soon(self._call_connection_lost, None)
  File "C:\Users\aramani\AppData\Local\Programs\Python\Python312\Lib\asyncio\base_events.py", line 794, in call_soon
    self._check_closed()
  File "C:\Users\aramani\AppData\Local\Programs\Python\Python312\Lib\asyncio\base_events.py", line 540, in _check_closed
    raise RuntimeError('Event loop is closed')
RuntimeError: Event loop is closed
[31m[1mERROR   [0m asyncio:base_events.py:1826 Task exception was never retrieved
future: <Task finished name='Task-32' coro=<AsyncClient.aclose() done, defined at C:\Users\aramani\PycharmProjects\PyRITxAllurexApplause\.venv\Lib\site-packages\httpx\_client.py:2024> exception=RuntimeError('Event loop is closed')>
Traceback (most recent call last):
  File "C:\Users\aramani\PycharmProjects\PyRITxAllurexApplause\.venv\Lib\site-packages\httpx\_client.py", line 2031, in aclose
    await self._transport.aclose()
  File "C:\Users\aramani\PycharmProjects\PyRITxAllurexApplause\.venv\Lib\site-packages\httpx\_transports\default.py", line 389, in aclose
    await self._pool.aclose()
  File "C:\Users\aramani\PycharmProjects\PyRITxAllurexApplause\.venv\Lib\site-packages\httpcore\_async\connection_pool.py", line 353, in aclose
    await self._close_connections(closing_connections)
  File "C:\Users\aramani\PycharmProjects\PyRITxAllurexApplause\.venv\Lib\site-packages\httpcore\_async\connection_pool.py", line 345, in _close_connections
    await connection.aclose()
  File "C:\Users\aramani\PycharmProjects\PyRITxAllurexApplause\.venv\Lib\site-packages\httpcore\_async\connection.py", line 173, in aclose
    await self._connection.aclose()
  File "C:\Users\aramani\PycharmProjects\PyRITxAllurexApplause\.venv\Lib\site-packages\httpcore\_async\http11.py", line 258, in aclose
    await self._network_stream.aclose()
  File "C:\Users\aramani\PycharmProjects\PyRITxAllurexApplause\.venv\Lib\site-packages\httpcore\_backends\anyio.py", line 53, in aclose
    await self._stream.aclose()
  File "C:\Users\aramani\PycharmProjects\PyRITxAllurexApplause\.venv\Lib\site-packages\anyio\streams\tls.py", line 201, in aclose
    await self.transport_stream.aclose()
  File "C:\Users\aramani\PycharmProjects\PyRITxAllurexApplause\.venv\Lib\site-packages\anyio\_backends\_asyncio.py", line 1306, in aclose
    self._transport.close()
  File "C:\Users\aramani\AppData\Local\Programs\Python\Python312\Lib\asyncio\proactor_events.py", line 109, in close
    self._loop.call_soon(self._call_connection_lost, None)
  File "C:\Users\aramani\AppData\Local\Programs\Python\Python312\Lib\asyncio\base_events.py", line 794, in call_soon
    self._check_closed()
  File "C:\Users\aramani\AppData\Local\Programs\Python\Python312\Lib\asyncio\base_events.py", line 540, in _check_closed
    raise RuntimeError('Event loop is closed')
RuntimeError: Event loop is closed
[31m[1mERROR   [0m asyncio:base_events.py:1826 Task exception was never retrieved
future: <Task finished name='Task-33' coro=<AsyncClient.aclose() done, defined at C:\Users\aramani\PycharmProjects\PyRITxAllurexApplause\.venv\Lib\site-packages\httpx\_client.py:2024> exception=RuntimeError('Event loop is closed')>
Traceback (most recent call last):
  File "C:\Users\aramani\PycharmProjects\PyRITxAllurexApplause\.venv\Lib\site-packages\httpx\_client.py", line 2031, in aclose
    await self._transport.aclose()
  File "C:\Users\aramani\PycharmProjects\PyRITxAllurexApplause\.venv\Lib\site-packages\httpx\_transports\default.py", line 389, in aclose
    await self._pool.aclose()
  File "C:\Users\aramani\PycharmProjects\PyRITxAllurexApplause\.venv\Lib\site-packages\httpcore\_async\connection_pool.py", line 353, in aclose
    await self._close_connections(closing_connections)
  File "C:\Users\aramani\PycharmProjects\PyRITxAllurexApplause\.venv\Lib\site-packages\httpcore\_async\connection_pool.py", line 345, in _close_connections
    await connection.aclose()
  File "C:\Users\aramani\PycharmProjects\PyRITxAllurexApplause\.venv\Lib\site-packages\httpcore\_async\connection.py", line 173, in aclose
    await self._connection.aclose()
  File "C:\Users\aramani\PycharmProjects\PyRITxAllurexApplause\.venv\Lib\site-packages\httpcore\_async\http11.py", line 258, in aclose
    await self._network_stream.aclose()
  File "C:\Users\aramani\PycharmProjects\PyRITxAllurexApplause\.venv\Lib\site-packages\httpcore\_backends\anyio.py", line 53, in aclose
    await self._stream.aclose()
  File "C:\Users\aramani\PycharmProjects\PyRITxAllurexApplause\.venv\Lib\site-packages\anyio\streams\tls.py", line 201, in aclose
    await self.transport_stream.aclose()
  File "C:\Users\aramani\PycharmProjects\PyRITxAllurexApplause\.venv\Lib\site-packages\anyio\_backends\_asyncio.py", line 1306, in aclose
    self._transport.close()
  File "C:\Users\aramani\AppData\Local\Programs\Python\Python312\Lib\asyncio\proactor_events.py", line 109, in close
    self._loop.call_soon(self._call_connection_lost, None)
  File "C:\Users\aramani\AppData\Local\Programs\Python\Python312\Lib\asyncio\base_events.py", line 794, in call_soon
    self._check_closed()
  File "C:\Users\aramani\AppData\Local\Programs\Python\Python312\Lib\asyncio\base_events.py", line 540, in _check_closed
    raise RuntimeError('Event loop is closed')
RuntimeError: Event loop is closed
[31m[1mERROR   [0m asyncio:base_events.py:1826 Task exception was never retrieved
future: <Task finished name='Task-34' coro=<AsyncClient.aclose() done, defined at C:\Users\aramani\PycharmProjects\PyRITxAllurexApplause\.venv\Lib\site-packages\httpx\_client.py:2024> exception=RuntimeError('Event loop is closed')>
Traceback (most recent call last):
  File "C:\Users\aramani\PycharmProjects\PyRITxAllurexApplause\.venv\Lib\site-packages\httpx\_client.py", line 2031, in aclose
    await self._transport.aclose()
  File "C:\Users\aramani\PycharmProjects\PyRITxAllurexApplause\.venv\Lib\site-packages\httpx\_transports\default.py", line 389, in aclose
    await self._pool.aclose()
  File "C:\Users\aramani\PycharmProjects\PyRITxAllurexApplause\.venv\Lib\site-packages\httpcore\_async\connection_pool.py", line 353, in aclose
    await self._close_connections(closing_connections)
  File "C:\Users\aramani\PycharmProjects\PyRITxAllurexApplause\.venv\Lib\site-packages\httpcore\_async\connection_pool.py", line 345, in _close_connections
    await connection.aclose()
  File "C:\Users\aramani\PycharmProjects\PyRITxAllurexApplause\.venv\Lib\site-packages\httpcore\_async\connection.py", line 173, in aclose
    await self._connection.aclose()
  File "C:\Users\aramani\PycharmProjects\PyRITxAllurexApplause\.venv\Lib\site-packages\httpcore\_async\http11.py", line 258, in aclose
    await self._network_stream.aclose()
  File "C:\Users\aramani\PycharmProjects\PyRITxAllurexApplause\.venv\Lib\site-packages\httpcore\_backends\anyio.py", line 53, in aclose
    await self._stream.aclose()
  File "C:\Users\aramani\PycharmProjects\PyRITxAllurexApplause\.venv\Lib\site-packages\anyio\streams\tls.py", line 201, in aclose
    await self.transport_stream.aclose()
  File "C:\Users\aramani\PycharmProjects\PyRITxAllurexApplause\.venv\Lib\site-packages\anyio\_backends\_asyncio.py", line 1306, in aclose
    self._transport.close()
  File "C:\Users\aramani\AppData\Local\Programs\Python\Python312\Lib\asyncio\proactor_events.py", line 109, in close
    self._loop.call_soon(self._call_connection_lost, None)
  File "C:\Users\aramani\AppData\Local\Programs\Python\Python312\Lib\asyncio\base_events.py", line 794, in call_soon
    self._check_closed()
  File "C:\Users\aramani\AppData\Local\Programs\Python\Python312\Lib\asyncio\base_events.py", line 540, in _check_closed
    raise RuntimeError('Event loop is closed')
RuntimeError: Event loop is closed